# Python 的 `except` 怪癖

让我来展示一下我最喜欢的Python怪癖。你希望这段python代码做什么?

```python
e = 2.718
try:
    1/0
except ZeroDivisionError as e:
    pass
print(e)
```

如果你是从另一种编程语言过来学习Python的，你可能希望`except`子句引入嵌套范围，因此在子句中赋值给`e`不会影响外部作用域中已有的`e`变量。然而，在Python中，控制结构通常不引入嵌套作用域(列表推导是一个例外)，所以如果你有更多的Python经验，你可能会期望它打印一个 `ZeroDivisionError` 实例。

实际上，在标准CPython实现中，它什么也不打印；相反，最后一行将引发一个 `NameError`。这是一个bug吗?事实上，这是[故意的](https://bugs.python.org/issue1631942)。如果查看 except 子句生成的字节码，可以看到:

```
LOAD_CONST 0 (None)
STORE_NAME 1 (e)
DELETE_NAME 1
```

当控制流退出 `except` 块时，Python将从作用域中删除该名称。为什么？因为异常持有对当前栈帧的引用，该栈帧包含作用域内的所有内容。由于Python主要是通过引用计数来管理内存主体的，这意味着当前作用域内的任何内容都不会被释放，直到下一轮垃圾收集运行 (如果有的话)。目前的行为是内存使用、易于实现和语言整洁之间的折衷。它有点缺点，但我认为它体现了我喜欢Python的一点：不让纯粹性妨碍实用性。

但这只解释了 `DELETE_NAME` 指令。为什么CPython把`e`设为`None`，如果它要在之后立即删除它？好吧，设想你和CPython团队有相同的想法，并且决定在 `except` t块的末尾清理异常引用:

```python
try:
    1/0
except ZeroDivisionError as e:
    ...
    del e
```

在 `except` 块的末尾，CPython将尝试删除你已经删除的名字`e` ！为了解决这个问题，CPython在删除`e`之前赋值`e = None`，以确保`e`存在。